import { describe, it, expect, vi } from 'vitest';
import { render, screen } from '../../test/test-utils';
import ErrorBoundary from '../ErrorBoundary';

// Component that throws an error for testing
const ThrowError = ({ shouldThrow }: { shouldThrow: boolean }) => {
  if (shouldThrow) {
    throw new Error('Test error');
  }
  return <div>No error</div>;
};

describe('ErrorBoundary', () => {
  it('renders children when there is no error', () => {
    render(
      <ErrorBoundary>
        <ThrowError shouldThrow={false} />
      </ErrorBoundary>
    );
    
    expect(screen.getByText('No error')).toBeInTheDocument();
  });

  it('renders error UI when there is an error', () => {
    // Suppress console.error for this test
    const consoleSpy = vi.spyOn(console, 'error').mockImplementation(() => {});
    
    render(
      <ErrorBoundary>
        <ThrowError shouldThrow={true} />
      </ErrorBoundary>
    );
    
    expect(screen.getByText('Oops! Something went wrong')).toBeInTheDocument();
    expect(screen.getByText('Try Again')).toBeInTheDocument();
    expect(screen.getByText('Go Home')).toBeInTheDocument();
    
    consoleSpy.mockRestore();
  });

  it('renders custom fallback when provided', () => {
    const consoleSpy = vi.spyOn(console, 'error').mockImplementation(() => {});
    const customFallback = <div>Custom error message</div>;
    
    render(
      <ErrorBoundary fallback={customFallback}>
        <ThrowError shouldThrow={true} />
      </ErrorBoundary>
    );
    
    expect(screen.getByText('Custom error message')).toBeInTheDocument();
    
    consoleSpy.mockRestore();
  });
});